Workbook

Sheet Summary
A1: PRUDENTIAL PLC - DCF VALUATION SUMMARY
A2: Investment Recommendation & Valuation Analysis
A3: Prepared: May 2026 | by Vismay Somi Reddy
A5: INVESTMENT RECOMMENDATION
A7: Rating: | B7: STRONG BUY
A8: Target Price: | B8: =DCF!B65 -> 28.387186
A9: Current Price: | B9: =DCF!B67 -> 11.35
A10: Upside Potential: | B10: =DCF!B68 -> 1.5010736
A12: Key Valuation Metrics
A14: Enterprise Value (£m) | B14: =DCF!B50 -> 69447.391
A15: Equity Value (£m) | B15: =DCF!B58 -> 71865.391
A16: Fair Value per Share (£) | B16: =DCF!B65 -> 28.387186
A17: WACC | B17: =DCF!B29 -> 0.10311179
A18: Terminal Growth Rate | B18: =Assumptions!B23 -> 0.025
A20: VALUATION RANGE (SENSITIVITY ANALYSIS)
A22: Bear Case (£) | B22: 23.58
A23: Base Case (£) | B23: =DCF!B65 -> 28.387186
A24: Bull Case (£) | B24: 36.7
A26: INVESTMENT THESIS
A28: 1. Prudential trades at £11.35, offering 150% upside to DCF fair value of £28.39
A29: 2. Strong cash flow generation: 5-year FCF CAGR of 6.3% (£4.6B to £6.2B)
A30: 3. Robust valuation: Even in bear case (WACC 11.3%, terminal growth 1.5%), fair value of £23.58 implies 108% upside
A31: 4. Asia-focused growth strategy provides exposure to faster-growing emerging markets
A32: 5. Conservative capital structure (84.5% equity, 15.5% debt) provides financial stability
A35: KEY RISKS
A37: 1. Regulatory risk: Changes in insurance regulations across Asia markets
A38: 2. Market risk: Equity market volatility affects investment portfolio returns
A39: 3. Geographic concentration: Heavy Asia exposure creates regional dependency
A40: 4. Interest rate risk: Rising rates could pressure valuation multiples
A41: 5. Execution risk: Growth targets depend on successful market penetration
A44: MODEL ASSUMPTIONS
A46: Revenue Growth (2026-2030): | B46: 8.0% → 5.5%
A47: EBIT Margin: | B47: 18.0% - 19.0%
A48: Capex % of Revenue: | B48: 0.005
A49: Tax Rate: | B49: 0.2

Sheet Assumptions
A1: PRUDENTIAL PLC - DCF MODEL ASSUMPTIONS
A2: All figures in millions (GBP unless stated)
A4: Year | B4: 2022 | C4: 2023 | D4: 2024 | E4: 2025 | F4: 2026E | G4: 2027E | H4: 2028E | I4: 2029E | J4: 2030E
A6: KEY HISTORICAL FINANCIALS
A8: Total Revenue | B8: -21220 | C8: 19148 | D8: 16211 | E8: 27393
A9: EBIT | B9: -443 | C9: 2269 | D9: 3124 | E9: 5124
A10: Net Income | B10: -1007 | C10: 1701 | D10: 2285 | E10: 3978
A11: Operating Cash Flow | B11: 1078 | C11: 832 | D11: 3609 | E11: 2450
A12: Capex | B12: -34 | C12: -44 | D12: -101 | E12: -104
A13: Free Cash Flow | B13: 1044 | C13: 788 | D13: 3508 | E13: 2346
A14: Total Debt | B14: 5076 | C14: 4874 | D14: 4722 | E14: 5290
A16: PROJECTION ASSUMPTIONS
A18: Revenue Growth Rate | F18: 0.08 | G18: 0.075 | H18: 0.065 | I18: 0.06 | J18: 0.055
A19: EBIT Margin % | B19: =B9/B8 -> 0.020876532 | C19: =C9/C8 -> 0.11849802 | D19: =D9/D8 -> 0.19270865 | E19: =E9/E8 -> 0.18705509 | F19: 0.18 | G19: 0.18 | H19: 0.185 | I19: 0.185 | J19: 0.19
A20: Capex % of Revenue | B20: =ABS(B12)/B8 -> -0.001602262 | C20: =ABS(C12)/C8 -> 0.0022978901 | D20: =ABS(D12)/D8 -> 0.0062303374 | E20: =ABS(E12)/E8 -> 0.0037965904 | F20: 0.005 | G20: 0.005 | H20: 0.005 | I20: 0.005 | J20: 0.005
A21: Tax Rate | B21: 0.2 | C21: 0.2 | D21: 0.2 | E21: 0.2 | F21: 0.2 | G21: 0.2 | H21: 0.2 | I21: 0.2 | J21: 0.2
A23: Terminal Growth Rate | B23: 0.025

Sheet Income_Statement
A1: PRUDENTIAL PLC - INCOME STATEMENT
A2: All figures in millions GBP
A4: Item | B4: 2022 | C4: 2023 | D4: 2024 | E4: 2025 | F4: 2026E | G4: 2027E | H4: 2028E | I4: 2029E | J4: 2030E
A6: Revenue | B6: =Assumptions!B8 -> -21220 | C6: =Assumptions!C8 -> 19148 | D6: =Assumptions!D8 -> 16211 | E6: =Assumptions!E8 -> 27393 | F6: =E6*(1+Assumptions!F18) -> 29584.44 | G6: =F6*(1+Assumptions!G18) -> 31803.273 | H6: =G6*(1+Assumptions!H18) -> 33870.486 | I6: =H6*(1+Assumptions!I18) -> 35902.715 | J6: =I6*(1+Assumptions!J18) -> 37877.364
A8: EBIT | B8: =Assumptions!B9 -> -443 | C8: =Assumptions!C9 -> 2269 | D8: =Assumptions!D9 -> 3124 | E8: =Assumptions!E9 -> 5124 | F8: =F6*Assumptions!F19 -> 5325.1992 | G8: =G6*Assumptions!G19 -> 5724.5891 | H8: =H6*Assumptions!H19 -> 6266.0399 | I8: =I6*Assumptions!I19 -> 6642.0023 | J8: =J6*Assumptions!J19 -> 7196.6992
A10: Interest Expense | B10: 183 | C10: 183 | D10: 183 | E10: 183 | F10: 183 | G10: 183 | H10: 183 | I10: 183 | J10: 183
A12: Pre-Tax Income | B12: =B8-B10 -> -626 | C12: =C8-C10 -> 2086 | D12: =D8-D10 -> 2941 | E12: =E8-E10 -> 4941 | F12: =F8-F10 -> 5142.1992 | G12: =G8-G10 -> 5541.5891 | H12: =H8-H10 -> 6083.0399 | I12: =I8-I10 -> 6459.0023 | J12: =J8-J10 -> 7013.6992
A14: Tax | B14: =B12*Assumptions!B21 -> -125.2 | C14: =C12*Assumptions!C21 -> 417.2 | D14: =D12*Assumptions!D21 -> 588.2 | E14: =E12*Assumptions!E21 -> 988.2 | F14: =F12*Assumptions!F21 -> 1028.4398 | G14: =G12*Assumptions!G21 -> 1108.3178 | H14: =H12*Assumptions!H21 -> 1216.608 | I14: =I12*Assumptions!I21 -> 1291.8005 | J14: =J12*Assumptions!J21 -> 1402.7398
A16: Net Income | B16: =B12-B14 -> -500.8 | C16: =C12-C14 -> 1668.8 | D16: =D12-D14 -> 2352.8 | E16: =E12-E14 -> 3952.8 | F16: =F12-F14 -> 4113.7594 | G16: =G12-G14 -> 4433.2713 | H16: =H12-H14 -> 4866.4319 | I16: =I12-I14 -> 5167.2018 | J16: =J12-J14 -> 5610.9594

Sheet Balance_Sheet
A1: PRUDENTIAL PLC - BALANCE SHEET
A2: All figures in millions GBP
A4: Item | B4: 2022 | C4: 2023 | D4: 2024 | E4: 2025 | F4: 2026E | G4: 2027E | H4: 2028E | I4: 2029E | J4: 2030E
A6: ASSETS
A8: Cash & Equivalents | B8: 5514 | C8: 4751 | D8: 5772 | E8: 7708 | F8: =E8*(1+Assumptions!F18) -> 8324.64 | G8: =F8*(1+Assumptions!G18) -> 8948.988 | H8: =G8*(1+Assumptions!H18) -> 9530.6722 | I8: =H8*(1+Assumptions!I18) -> 10102.513 | J8: =I8*(1+Assumptions!J18) -> 10658.151
A9: Other Current Assets | B9: =Income_Statement!B6*0.15 -> -3183 | C9: =Income_Statement!C6*0.15 -> 2872.2 | D9: =Income_Statement!D6*0.15 -> 2431.65 | E9: =Income_Statement!E6*0.15 -> 4108.95 | F9: =Income_Statement!F6*0.15 -> 4437.666 | G9: =Income_Statement!G6*0.15 -> 4770.491 | H9: =Income_Statement!H6*0.15 -> 5080.5729 | I9: =Income_Statement!I6*0.15 -> 5385.4072 | J9: =Income_Statement!J6*0.15 -> 5681.6046
A10: Total Current Assets | B10: =B8+B9 -> 2331 | C10: =C8+C9 -> 7623.2 | D10: =D8+D9 -> 8203.65 | E10: =E8+E9 -> 11816.95 | F10: =F8+F9 -> 12762.306 | G10: =G8+G9 -> 13719.479 | H10: =H8+H9 -> 14611.245 | I10: =I8+I9 -> 15487.92 | J10: =J8+J9 -> 16339.755
A12: Fixed Assets (Net) | B12: 11957 | C12: 12941 | D12: 12820 | E12: 15257 | F12: =E12+ABS(Cash_Flow!F14) -> 15404.922 | G12: =F12+ABS(Cash_Flow!G14) -> 15563.939 | H12: =G12+ABS(Cash_Flow!H14) -> 15733.291 | I12: =H12+ABS(Cash_Flow!I14) -> 15912.805 | J12: =I12+ABS(Cash_Flow!J14) -> 16102.191
A14: TOTAL ASSETS | B14: =B10+B12 -> 14288 | C14: =C10+C12 -> 20564.2 | D14: =D10+D12 -> 21023.65 | E14: =E10+E12 -> 27073.95 | F14: =F10+F12 -> 28167.228 | G14: =G10+G12 -> 29283.418 | H14: =H10+H12 -> 30344.536 | I14: =I10+I12 -> 31400.724 | J14: =J10+J12 -> 32441.947
A16: LIABILITIES
A18: Total Debt | B18: 5076 | C18: 4874 | D18: 4722 | E18: 5290 | F18: =E18 -> 5290 | G18: =F18 -> 5290 | H18: =G18 -> 5290 | I18: =H18 -> 5290 | J18: =I18 -> 5290 | L18: ← Projected (assuming debt is stable/I am holding it constant)
A19: Other Liabilities | B19: =B14-B18-B22 -> -7686 | C19: =C14-C18-C22 -> -2292.8 | D19: =D14-D18-D22 -> -2372.35 | E19: =E14-E18-E22 -> 423.95 | F19: =F14-F18-F22 -> -2596.5312 | G19: =G14-G18-G22 -> -5913.6132 | H19: =H14-H18-H22 -> -9718.9265 | I19: =I14-I18-I22 -> -13829.94 | J19: =J14-J18-J22 -> -18399.677
A20: TOTAL LIABILITIES | B20: =B18+B19 -> -2610 | C20: =C18+C19 -> 2581.2 | D20: =D18+D19 -> 2349.65 | E20: =E18+E19 -> 5713.95 | F20: =F18+F19 -> 2693.4688 | G20: =G18+G19 -> -623.61316 | H20: =H18+H19 -> -4428.9265 | I20: =I18+I19 -> -8539.94 | J20: =J18+J19 -> -13109.677
A21: EQUITY
A22: Total Equity | B22: 16898 | C22: 17983 | D22: 18674 | E22: 21360 | F22: =E22+Income_Statement!F16 -> 25473.759 | G22: =F22+Income_Statement!G16 -> 29907.031 | H22: =G22+Income_Statement!H16 -> 34773.463 | I22: =H22+Income_Statement!I16 -> 39940.664 | J22: =I22+Income_Statement!J16 -> 45551.624
A24: TOTAL LIABILITIES + EQUITY | B24: =B20+B22 -> 14288 | C24: =C20+C22 -> 20564.2 | D24: =D20+D22 -> 21023.65 | E24: =E20+E22 -> 27073.95 | F24: =F20+F22 -> 28167.228 | G24: =G20+G22 -> 29283.418 | H24: =H20+H22 -> 30344.536 | I24: =I20+I22 -> 31400.724 | J24: =J20+J22 -> 32441.947
A26: BALANCE CHECK: | B26: =IF(B14=B24,"BALANCED","ERROR") -> BALANCED | C26: =IF(C14=C24,"BALANCED","ERROR") -> BALANCED | D26: =IF(D14=D24,"BALANCED","ERROR") -> BALANCED | E26: =IF(E14=E24,"BALANCED","ERROR") -> BALANCED | F26: =IF(F14=F24,"BALANCED","ERROR") -> BALANCED | G26: =IF(G14=G24,"BALANCED","ERROR") -> BALANCED | H26: =IF(H14=H24,"BALANCED","ERROR") -> BALANCED | I26: =IF(I14=I24,"BALANCED","ERROR") -> BALANCED | J26: =IF(J14=J24,"BALANCED","ERROR") -> BALANCED

Sheet Cash_Flow
A1: PRUDENTIAL PLC - CASH FLOW STATEMENT
A2: All figures in millions GBP
A4: Item | B4: 2022 | C4: 2023 | D4: 2024 | E4: 2025 | F4: 2026E | G4: 2027E | H4: 2028E | I4: 2029E | J4: 2030E
A6: Net Income | B6: =Income_Statement!B16 -> -500.8 | C6: =Income_Statement!C16 -> 1668.8 | D6: =Income_Statement!D16 -> 2352.8 | E6: =Income_Statement!E16 -> 3952.8 | F6: =Income_Statement!F16 -> 4113.7594 | G6: =Income_Statement!G16 -> 4433.2713 | H6: =Income_Statement!H16 -> 4866.4319 | I6: =Income_Statement!I16 -> 5167.2018 | J6: =Income_Statement!J16 -> 5610.9594
A8: Depreciation & Amortization | B8: =Assumptions!B8*0.02 -> -424.4 | C8: =Assumptions!C8*0.02 -> 382.96 | D8: =Assumptions!D8*0.02 -> 324.22 | E8: =Assumptions!E8*0.02 -> 547.86 | F8: =Income_Statement!F6*0.02 -> 591.6888 | G8: =Income_Statement!G6*0.02 -> 636.06546 | H8: =Income_Statement!H6*0.02 -> 677.40971 | I8: =Income_Statement!I6*0.02 -> 718.0543 | J8: =Income_Statement!J6*0.02 -> 757.54728
A10: Change in Working Capital | B10: 0 | C10: 0 | D10: 0 | E10: 0 | F10: 0 | G10: 0 | H10: 0 | I10: 0 | J10: 0
A12: Operating Cash Flow | B12: =B6+B8-B10 -> -925.2 | C12: =C6+C8-C10 -> 2051.76 | D12: =D6+D8-D10 -> 2677.02 | E12: =E6+E8-E10 -> 4500.66 | F12: =F6+F8-F10 -> 4705.4482 | G12: =G6+G8-G10 -> 5069.3368 | H12: =H6+H8-H10 -> 5543.8416 | I12: =I6+I8-I10 -> 5885.2561 | J12: =J6+J8-J10 -> 6368.5066
A14: Capital Expenditures | B14: =Assumptions!B12 -> -34 | C14: =Assumptions!C12 -> -44 | D14: =Assumptions!D12 -> -101 | E14: =Assumptions!E12 -> -104 | F14: =-Income_Statement!F6*Assumptions!F20 -> -147.9222 | G14: =-Income_Statement!G6*Assumptions!G20 -> -159.01637 | H14: =-Income_Statement!H6*Assumptions!H20 -> -169.35243 | I14: =-Income_Statement!I6*Assumptions!I20 -> -179.51357 | J14: =-Income_Statement!J6*Assumptions!J20 -> -189.38682
A16: FREE CASH FLOW | B16: =B12+B14 -> -959.2 | C16: =C12+C14 -> 2007.76 | D16: =D12+D14 -> 2576.02 | E16: =E12+E14 -> 4396.66 | F16: =F12+F14 -> 4557.526 | G16: =G12+G14 -> 4910.3204 | H16: =H12+H14 -> 5374.4892 | I16: =I12+I14 -> 5705.7425 | J16: =J12+J14 -> 6179.1198

Sheet DCF
A1: PRUDENTIAL PLC - DCF VALUATION
A3: WACC CALCULATION
A5: Market Cap (Equity) | B5: =(1135/100)*2531.61378 -> 28733.816
A6: Total Debt | B6: =Assumptions!E14 -> 5290
A7: Total Capital (E + D) | B7: =B5+B6 -> 34023.816
A9: Weight of Equity (E/V) | B9: =B5/B7 -> 0.84452068
A10: Weight of Debt (D/V) | B10: =B6/B7 -> 0.15547932
A12: COST OF EQUITY CALCULATION
A14: Risk-Free Rate | B14: 0.045
A15: Beta | B15: 1.2
A16: Market Risk Premium | B16: 0.06
A18: Cost of Equity | B18: =B14+(B15*B16) -> 0.117
A20: COST OF DEBT CALCULATION
A22: Interest Expense | B22: =Income_Statement!E10 -> 183
A23: Total Debt | B23: =B6 -> 5290
A25: Cost of Debt (Pre-Tax) | B25: =B22/B23 -> 0.034593573
A26: Tax Rate | B26: =Assumptions!B21 -> 0.2
A27: Cost of Debt (After-Tax) | B27: =B25*(1-B26) -> 0.027674858
A29: WEIGHTED AVERAGE COST OF CAPITAL (WACC) | B29: =(B9*B18)+(B10*B27) -> 0.10311179
A32: DCF VALUATION
A34: Year | B34: 2026E | C34: 2027E | D34: 2028E | E34: 2029E | F34: 2030E
A35: Free Cash Flow | B35: =Cash_Flow!F16 -> 4557.526 | C35: =Cash_Flow!G16 -> 4910.3204 | D35: =Cash_Flow!H16 -> 5374.4892 | E35: =Cash_Flow!I16 -> 5705.7425 | F35: =Cash_Flow!J16 -> 6179.1198
A36: Discount Factor | B36: =1/(1+$B$29)^1 -> 0.90652644 | C36: =1/(1+$B$29)^2 -> 0.82179018 | D36: =1/(1+$B$29)^3 -> 0.74497453 | E36: =1/(1+$B$29)^4 -> 0.67533911 | F36: =1/(1+$B$29)^5 -> 0.61221276
A37: PV of FCF | B37: =B35*B36 -> 4131.5178 | C37: =C35*C36 -> 4035.2531 | D37: =D35*D36 -> 4003.8575 | E37: =E35*E36 -> 3853.3111 | F37: =F35*F36 -> 3782.936
A39: Sum of PV (5 years) | B39: =SUM(B37:F37) -> 19806.875
A41: TERMINAL VALUE CALCULATION
A43: Terminal Growth Rate | B43: =Assumptions!B23 -> 0.025
A44: 2030 Free Cash Flow | B44: =F35 -> 6179.1198
A46: Terminal Value | B46: =B44*(1+B43)/($B$29-B43) -> 81083.765
A48: PV of Terminal Value | B48: =B46*F36 -> 49640.515
A50: ENTERPRISE VALUE | B50: =B39+B48 -> 69447.391
A52: ADJUSTMENTS TO EQUITY VALUE
A54: Enterprise Value | B54: =B50 -> 69447.391
A55: Less: Total Debt | B55: =-B6 -> -5290
A56: Add: Cash & Equivalents | B56: 7708
A58: EQUITY VALUE | B58: =B54+B55+B56 -> 71865.391
A60: VALUATION PER SHARE
A62: Equity Value | B62: =B58 -> 71865.391
A63: Shares Outstanding (thousands) | B63: 2531613.8
A65: Fair Value per Share (£) | B65: =B62/B63*1000 -> 28.387186
...

Sheet Sensitivity
A1: PRUDENTIAL PLC - SENSITIVITY ANALYSIS
A2: Fair Value per Share (£) - Sensitivity to WACC & Terminal Growth
A5: WACC ↓ \ Term Growth → | B5: 0.015 | C5: 0.02 | D5: 0.025 | E5: 0.03 | F5: 0.035
A6: 0.093 | B6: =((DCF!$B$39+(DCF!$B$44*(1+B$5)/($A6-B$5)*(1/(1+$A6)^5)))+DCF!$B$55+DCF!$B$56)/(DCF!$B$63/1000) -> 29.139968 | C6: =((DCF!$B$39+(DCF!$B$44*(1+C$5)/($A6-C$5)*(1/(1+$A6)^5)))+DCF!$B$55+DCF!$B$56)/(DCF!$B$63/1000) -> 30.64173 | D6: =((DCF!$B$39+(DCF!$B$44*(1+D$5)/($A6-D$5)*(1/(1+$A6)^5)))+DCF!$B$55+DCF!$B$56)/(DCF!$B$63/1000) -> 32.364339 | E6: =((DCF!$B$39+(DCF!$B$44*(1+E$5)/($A6-E$5)*(1/(1+$A6)^5)))+DCF!$B$55+DCF!$B$56)/(DCF!$B$63/1000) -> 34.360379 | F6: =((DCF!$B$39+(DCF!$B$44*(1+F$5)/($A6-F$5)*(1/(1+$A6)^5)))+DCF!$B$55+DCF!$B$56)/(DCF!$B$63/1000) -> 36.700562
A7: 0.098 | B7: =((DCF!$B$39+(DCF!$B$44*(1+B$5)/($A7-B$5)*(1/(1+$A7)^5)))+DCF!$B$55+DCF!$B$56)/(DCF!$B$63/1000) -> 27.481684 | C7: =((DCF!$B$39+(DCF!$B$44*(1+C$5)/($A7-C$5)*(1/(1+$A7)^5)))+DCF!$B$55+DCF!$B$56)/(DCF!$B$63/1000) -> 28.778615 | D7: =((DCF!$B$39+(DCF!$B$44*(1+D$5)/($A7-D$5)*(1/(1+$A7)^5)))+DCF!$B$55+DCF!$B$56)/(DCF!$B$63/1000) -> 30.253209 | E7: =((DCF!$B$39+(DCF!$B$44*(1+E$5)/($A7-E$5)*(1/(1+$A7)^5)))+DCF!$B$55+DCF!$B$56)/(DCF!$B$63/1000) -> 31.944655 | F7: =((DCF!$B$39+(DCF!$B$44*(1+F$5)/($A7-F$5)*(1/(1+$A7)^5)))+DCF!$B$55+DCF!$B$56)/(DCF!$B$63/1000) -> 33.904584
A8: 0.103 | B8: =((DCF!$B$39+(DCF!$B$44*(1+B$5)/($A8-B$5)*(1/(1+$A8)^5)))+DCF!$B$55+DCF!$B$56)/(DCF!$B$63/1000) -> 26.022815 | C8: =((DCF!$B$39+(DCF!$B$44*(1+C$5)/($A8-C$5)*(1/(1+$A8)^5)))+DCF!$B$55+DCF!$B$56)/(DCF!$B$63/1000) -> 27.151666 | D8: =((DCF!$B$39+(DCF!$B$44*(1+D$5)/($A8-D$5)*(1/(1+$A8)^5)))+DCF!$B$55+DCF!$B$56)/(DCF!$B$63/1000) -> 28.42524 | E8: =((DCF!$B$39+(DCF!$B$44*(1+E$5)/($A8-E$5)*(1/(1+$A8)^5)))+DCF!$B$55+DCF!$B$56)/(DCF!$B$63/1000) -> 29.873277 | F8: =((DCF!$B$39+(DCF!$B$44*(1+F$5)/($A8-F$5)*(1/(1+$A8)^5)))+DCF!$B$55+DCF!$B$56)/(DCF!$B$63/1000) -> 31.534261
A9: 0.108 | B9: =((DCF!$B$39+(DCF!$B$44*(1+B$5)/($A9-B$5)*(1/(1+$A9)^5)))+DCF!$B$55+DCF!$B$56)/(DCF!$B$63/1000) -> 24.730874 | C9: =((DCF!$B$39+(DCF!$B$44*(1+C$5)/($A9-C$5)*(1/(1+$A9)^5)))+DCF!$B$55+DCF!$B$56)/(DCF!$B$63/1000) -> 25.72028 | D9: =((DCF!$B$39+(DCF!$B$44*(1+D$5)/($A9-D$5)*(1/(1+$A9)^5)))+DCF!$B$55+DCF!$B$56)/(DCF!$B$63/1000) -> 26.828892 | E9: =((DCF!$B$39+(DCF!$B$44*(1+E$5)/($A9-E$5)*(1/(1+$A9)^5)))+DCF!$B$55+DCF!$B$56)/(DCF!$B$63/1000) -> 28.079633 | F9: =((DCF!$B$39+(DCF!$B$44*(1+F$5)/($A9-F$5)*(1/(1+$A9)^5)))+DCF!$B$55+DCF!$B$56)/(DCF!$B$63/1000) -> 29.501708
A10: 0.113 | B10: =((DCF!$B$39+(DCF!$B$44*(1+B$5)/($A10-B$5)*(1/(1+$A10)^5)))+DCF!$B$55+DCF!$B$56)/(DCF!$B$63/1000) -> 23.580013 | C10: =((DCF!$B$39+(DCF!$B$44*(1+C$5)/($A10-C$5)*(1/(1+$A10)^5)))+DCF!$B$55+DCF!$B$56)/(DCF!$B$63/1000) -> 24.452601 | D10: =((DCF!$B$39+(DCF!$B$44*(1+D$5)/($A10-D$5)*(1/(1+$A10)^5)))+DCF!$B$55+DCF!$B$56)/(DCF!$B$63/1000) -> 25.424348 | E10: =((DCF!$B$39+(DCF!$B$44*(1+E$5)/($A10-E$5)*(1/(1+$A10)^5)))+DCF!$B$55+DCF!$B$56)/(DCF!$B$63/1000) -> 26.513172 | F10: =((DCF!$B$39+(DCF!$B$44*(1+F$5)/($A10-F$5)*(1/(1+$A10)^5)))+DCF!$B$55+DCF!$B$56)/(DCF!$B$63/1000) -> 27.741589
A12: KEY INSIGHTS
A14: Valuation Range: £23.58 - £36.70
A15: Current Price: £11.35
A16: Minimum Upside: 108%
A17: Maximum Upside: 223%
A19: CONCLUSION: Prudential remains significantly undervalued across all reasonable scenarios. Even in the most conservative case (£23.58), the stock offers 108% upside vs current price of £11.35, demonstrating a robust investment thesis with asymmetric risk-reward profile.
